<?xml version="1.0"?>
<robot name="learningrobot">

<!--base_link-->
    <link name="base_link">
        <visual>
            <origin xyz="0.0 0.0 0.0" rpy="0.0 0.0 0.0"/>
            <geometry>
                <box size="0.4 0.3 0.06"/>
            </geometry>
            <material name = "red" >
                <color rgba="1.0 0.0 0.0 1.0"/>
            </material>
        </visual>
    </link>

    <link name="left_wheel_link">
        <visual >
            <origin xyz="0.0 0.0 0.0" rpy="1.5707 0.0 0.0"/>
            <geometry>
                <cylinder radius="0.09" length="0.06"/>
            </geometry>
            <material name="green">
                <color rgba="0.0 1.0 0.0 1.0"/>
            </material>
        </visual>
    </link>

<!--left_wheel-->>
    <joint name="left_wheel_joint" type="continuous">
        <origin xyz="-0.1 0.15 0.0" rpy="0.0 0.0 0.0"/>
        <parent link="base_link"/>
        <child link="left_wheel_link"/>
        <axis xyz="0.0 1.0 0.0"/>
    </joint>

    <link name="right_wheel_link">
        <visual >
            <origin xyz="0.0 0.0 0.0" rpy="1.5707 0.0 0.0"/>
            <geometry>
                <cylinder radius="0.09" length="0.06"/>
            </geometry>
            <material name="green">
                <color rgba="0.0 1.0 0.0 1.0"/>
            </material>
        </visual>
    </link>

<!--right_wheel-->
    <joint name="right_wheel_joint" type="continuous">
        <origin xyz="-0.1 -0.15 0.0" rpy="0.0 0.0 0.0"/>
        <parent link="base_link"/>
        <child link="right_wheel_link"/>
        <axis xyz="0.0 1.0 0.0"/>
    </joint>

    <link name="caster_link">
        <visual>
            <origin xyz="0.0 0.0 0.0" rpy="0.0 0.0 0.0"/>
            <geometry>
                <sphere radius="0.03"/>
            </geometry>
            <material name="blue">
                <color rgba="0.0 0.0 1.0 1.0"/>
            </material>
        </visual>
    </link>

    <joint name="caster_joint" type="continuous">
        <origin xyz="0.17 0.0 -0.06" rpy="0.0 0.0 0.0"/>
        <parent link="base_link"/>
        <child link="caster_link"/>
        <axis xyz="0.0 1.0 0.0"/>
    </joint>

<!--camera-->
    <link name="camera_link">
        <visual>
            <origin xyz="0.0 0.0 0.0" rpy="0.0 0.0 1.5707"/>
            <geometry>
                <mesh filename="package://learningrobot_description/meshes/kinect.dae"/>
            </geometry>
        </visual>
    </link>

    <joint name="camera_joint" type="fixed">
        <origin xyz="0.16 0.0 0.065" rpy="0.0 0.0 0.0"/>
        <parent link="base_link"/>
        <child link="camera_link"/>
    </joint>

<!--lidar_support-->
    <link name="support_link">
        <visual>
            <origin xyz="0.0 0.0 0.0" rpy="0.0 0.0 0.0"/>
            <geometry>
                <cylinder radius="0.015" length="0.1"/>
            </geometry>
            <material name="white">
                <color rgba="1.0 1.0 1.0 1.0"/>
            </material>
        </visual>
    </link>

    <joint name="support_joint" type="fixed">
        <origin xyz="0.0 0.0 0.08" rpy="0.0 0.0 0.0"/>
        <parent link="base_link"/>
        <child link="support_link"/>
        <axis xyz="0.0 0.0 0.0"/>
    </joint>

<!--lidar-->
    <link name="lidar_link">
        <visual name="">
            <origin xyz="0.0 0.0 0.0" rpy="0.0 0.0 0.0"/>
            <geometry>
                <cylinder radius="0.05" length="0.05"/>
            </geometry>
            <material name="black">
                <color rgba="0.0 0.0 0.0 1.0"/>
            </material>
        </visual>
    </link>
    
    <joint name="lidar_joint" type="continuous">
        <origin xyz="0.0 0.0 0.075" rpy="0.0 0.0 0.0"/>
        <parent link="support_link"/>
        <child link="lidar_link"/>
        <axis xyz="0.0 0.0 1.0"/>
    </joint>

</robot>